[2021-11-03 12:14:45,593] {taskinstance.py:1035} INFO - Dependencies all met for <TaskInstance: file_upload.get_file scheduled__2021-11-02T00:00:00+00:00 [queued]>
[2021-11-03 12:14:45,606] {taskinstance.py:1035} INFO - Dependencies all met for <TaskInstance: file_upload.get_file scheduled__2021-11-02T00:00:00+00:00 [queued]>
[2021-11-03 12:14:45,606] {taskinstance.py:1241} INFO - 
--------------------------------------------------------------------------------
[2021-11-03 12:14:45,607] {taskinstance.py:1242} INFO - Starting attempt 1 of 2
[2021-11-03 12:14:45,607] {taskinstance.py:1243} INFO - 
--------------------------------------------------------------------------------
[2021-11-03 12:14:45,631] {taskinstance.py:1262} INFO - Executing <Task(PythonOperator): get_file> on 2021-11-02 00:00:00+00:00
[2021-11-03 12:14:45,639] {standard_task_runner.py:52} INFO - Started process 32458 to run task
[2021-11-03 12:14:45,643] {standard_task_runner.py:76} INFO - Running: ['airflow', 'tasks', 'run', 'file_upload', 'get_file', 'scheduled__2021-11-02T00:00:00+00:00', '--job-id', '56', '--raw', '--subdir', 'DAGS_FOLDER/file_loadin.py', '--cfg-path', '/tmp/tmp6t9uqur9', '--error-file', '/tmp/tmpdv3p3pte']
[2021-11-03 12:14:45,648] {standard_task_runner.py:77} INFO - Job 56: Subtask get_file
[2021-11-03 12:14:45,705] {logging_mixin.py:109} INFO - Running <TaskInstance: file_upload.get_file scheduled__2021-11-02T00:00:00+00:00 [running]> on host user-Latitude-3410
[2021-11-03 12:14:45,773] {taskinstance.py:1414} INFO - Exporting the following env vars:
AIRFLOW_CTX_DAG_EMAIL=airflow@example.com
AIRFLOW_CTX_DAG_OWNER=airflow
AIRFLOW_CTX_DAG_ID=file_upload
AIRFLOW_CTX_TASK_ID=get_file
AIRFLOW_CTX_EXECUTION_DATE=2021-11-02T00:00:00+00:00
AIRFLOW_CTX_DAG_RUN_ID=scheduled__2021-11-02T00:00:00+00:00
[2021-11-03 12:14:45,888] {transport.py:1819} INFO - Connected (version 2.0, client OpenSSH_for_Windows_7.7)
[2021-11-03 12:14:46,841] {transport.py:1819} INFO - Authentication (publickey) failed.
[2021-11-03 12:14:46,923] {transport.py:1819} INFO - Authentication (publickey) failed.
[2021-11-03 12:14:47,060] {transport.py:1819} INFO - Authentication (password) successful!
[2021-11-03 12:14:47,227] {sftp.py:158} INFO - [chan 0] Opened sftp connection (server version 3)
[2021-11-03 12:14:47,228] {logging_mixin.py:109} INFO - name 'w' is not defined error of line number 24
[2021-11-03 12:14:47,228] {python.py:152} INFO - Done. Returned value was: None
[2021-11-03 12:14:47,242] {taskinstance.py:1280} INFO - Marking task as SUCCESS. dag_id=file_upload, task_id=get_file, execution_date=20211102T000000, start_date=20211103T064445, end_date=20211103T064447
[2021-11-03 12:14:47,298] {local_task_job.py:154} INFO - Task exited with return code 0
[2021-11-03 12:14:47,355] {local_task_job.py:264} INFO - 1 downstream tasks scheduled from follow-on schedule check
[2021-11-03 12:14:51,395] {taskinstance.py:1035} INFO - Dependencies all met for <TaskInstance: file_upload.get_file manual__2021-11-03T05:19:09.574659+00:00 [queued]>
[2021-11-03 12:14:51,436] {taskinstance.py:1035} INFO - Dependencies all met for <TaskInstance: file_upload.get_file manual__2021-11-03T05:19:09.574659+00:00 [queued]>
[2021-11-03 12:14:51,436] {taskinstance.py:1241} INFO - 
--------------------------------------------------------------------------------
[2021-11-03 12:14:51,436] {taskinstance.py:1242} INFO - Starting attempt 1 of 2
[2021-11-03 12:14:51,437] {taskinstance.py:1243} INFO - 
--------------------------------------------------------------------------------
[2021-11-03 12:14:51,488] {taskinstance.py:1262} INFO - Executing <Task(PythonOperator): get_file> on 2021-11-03 05:19:09.574659+00:00
[2021-11-03 12:14:51,499] {standard_task_runner.py:52} INFO - Started process 32619 to run task
[2021-11-03 12:14:51,534] {standard_task_runner.py:76} INFO - Running: ['airflow', 'tasks', 'run', 'file_upload', 'get_file', 'manual__2021-11-03T05:19:09.574659+00:00', '--job-id', '57', '--raw', '--subdir', 'DAGS_FOLDER/file_loadin.py', '--cfg-path', '/tmp/tmpegkzm8yj', '--error-file', '/tmp/tmp9w5buei3']
[2021-11-03 12:14:51,544] {standard_task_runner.py:77} INFO - Job 57: Subtask get_file
[2021-11-03 12:14:51,653] {logging_mixin.py:109} INFO - Running <TaskInstance: file_upload.get_file manual__2021-11-03T05:19:09.574659+00:00 [running]> on host user-Latitude-3410
[2021-11-03 12:14:51,736] {taskinstance.py:1414} INFO - Exporting the following env vars:
AIRFLOW_CTX_DAG_EMAIL=airflow@example.com
AIRFLOW_CTX_DAG_OWNER=airflow
AIRFLOW_CTX_DAG_ID=file_upload
AIRFLOW_CTX_TASK_ID=get_file
AIRFLOW_CTX_EXECUTION_DATE=2021-11-03T05:19:09.574659+00:00
AIRFLOW_CTX_DAG_RUN_ID=manual__2021-11-03T05:19:09.574659+00:00
[2021-11-03 12:14:52,866] {transport.py:1819} INFO - Connected (version 2.0, client OpenSSH_for_Windows_7.7)
[2021-11-03 12:14:53,105] {transport.py:1819} INFO - Authentication (publickey) failed.
[2021-11-03 12:14:53,171] {transport.py:1819} INFO - Authentication (publickey) failed.
[2021-11-03 12:14:53,318] {transport.py:1819} INFO - Authentication (password) successful!
[2021-11-03 12:14:53,503] {sftp.py:158} INFO - [chan 0] Opened sftp connection (server version 3)
[2021-11-03 12:14:53,504] {logging_mixin.py:109} INFO - name 'w' is not defined error of line number 24
[2021-11-03 12:14:53,504] {python.py:152} INFO - Done. Returned value was: None
[2021-11-03 12:14:53,521] {taskinstance.py:1280} INFO - Marking task as SUCCESS. dag_id=file_upload, task_id=get_file, execution_date=20211103T051909, start_date=20211103T064451, end_date=20211103T064453
[2021-11-03 12:14:53,572] {local_task_job.py:154} INFO - Task exited with return code 0
[2021-11-03 12:14:53,609] {local_task_job.py:264} INFO - 1 downstream tasks scheduled from follow-on schedule check
