[2021-10-14 17:35:20,247] {taskinstance.py:1035} INFO - Dependencies all met for <TaskInstance: example_variables.get_variable_value scheduled__2021-10-14T00:00:00+00:00 [queued]>
[2021-10-14 17:35:20,259] {taskinstance.py:1035} INFO - Dependencies all met for <TaskInstance: example_variables.get_variable_value scheduled__2021-10-14T00:00:00+00:00 [queued]>
[2021-10-14 17:35:20,259] {taskinstance.py:1241} INFO - 
--------------------------------------------------------------------------------
[2021-10-14 17:35:20,259] {taskinstance.py:1242} INFO - Starting attempt 1 of 1
[2021-10-14 17:35:20,259] {taskinstance.py:1243} INFO - 
--------------------------------------------------------------------------------
[2021-10-14 17:35:20,272] {taskinstance.py:1262} INFO - Executing <Task(BashOperator): get_variable_value> on 2021-10-14 00:00:00+00:00
[2021-10-14 17:35:20,275] {standard_task_runner.py:52} INFO - Started process 20517 to run task
[2021-10-14 17:35:20,282] {standard_task_runner.py:76} INFO - Running: ['airflow', 'tasks', 'run', 'example_variables', 'get_variable_value', 'scheduled__2021-10-14T00:00:00+00:00', '--job-id', '67', '--raw', '--subdir', 'DAGS_FOLDER/variable.py', '--cfg-path', '/tmp/tmpuvdffpi3', '--error-file', '/tmp/tmpdf2dug08']
[2021-10-14 17:35:20,285] {standard_task_runner.py:77} INFO - Job 67: Subtask get_variable_value
[2021-10-14 17:35:20,315] {logging_mixin.py:109} INFO - Running <TaskInstance: example_variables.get_variable_value scheduled__2021-10-14T00:00:00+00:00 [running]> on host user-Latitude-3410
[2021-10-14 17:35:20,346] {taskinstance.py:1686} ERROR - Task failed with exception
Traceback (most recent call last):
  File "/home/user/workspace/airflow/airflow_env/lib/python3.6/site-packages/airflow/models/taskinstance.py", line 1324, in _run_raw_task
    self._execute_task_with_callbacks(context)
  File "/home/user/workspace/airflow/airflow_env/lib/python3.6/site-packages/airflow/models/taskinstance.py", line 1406, in _execute_task_with_callbacks
    self.render_templates(context=context)
  File "/home/user/workspace/airflow/airflow_env/lib/python3.6/site-packages/airflow/models/taskinstance.py", line 2088, in render_templates
    self.task.render_template_fields(context)
  File "/home/user/workspace/airflow/airflow_env/lib/python3.6/site-packages/airflow/models/baseoperator.py", line 1057, in render_template_fields
    self._do_render_template_fields(self, self.template_fields, context, jinja_env, set())
  File "/home/user/workspace/airflow/airflow_env/lib/python3.6/site-packages/airflow/models/baseoperator.py", line 1070, in _do_render_template_fields
    rendered_content = self.render_template(content, context, jinja_env, seen_oids)
  File "/home/user/workspace/airflow/airflow_env/lib/python3.6/site-packages/airflow/models/baseoperator.py", line 1107, in render_template
    return jinja_env.from_string(content).render(**context)
  File "/home/user/workspace/airflow/airflow_env/lib/python3.6/site-packages/jinja2/environment.py", line 1090, in render
    self.environment.handle_exception()
  File "/home/user/workspace/airflow/airflow_env/lib/python3.6/site-packages/jinja2/environment.py", line 832, in handle_exception
    reraise(*rewrite_traceback_stack(source=source))
  File "/home/user/workspace/airflow/airflow_env/lib/python3.6/site-packages/jinja2/_compat.py", line 28, in reraise
    raise value.with_traceback(tb)
  File "<template>", line 1, in top-level template code
  File "/home/user/workspace/airflow/airflow_env/lib/python3.6/site-packages/jinja2/sandbox.py", line 407, in getattr
    value = getattr(obj, attribute)
  File "/home/user/workspace/airflow/airflow_env/lib/python3.6/site-packages/airflow/models/taskinstance.py", line 1841, in __getattr__
    self.var = Variable.get(item)
  File "/home/user/workspace/airflow/airflow_env/lib/python3.6/site-packages/airflow/models/variable.py", line 140, in get
    raise KeyError(f'Variable {key} does not exist')
KeyError: 'Variable val3 does not exist'
[2021-10-14 17:35:20,359] {taskinstance.py:1280} INFO - Marking task as FAILED. dag_id=example_variables, task_id=get_variable_value, execution_date=20211014T000000, start_date=20211014T120520, end_date=20211014T120520
[2021-10-14 17:35:20,375] {standard_task_runner.py:91} ERROR - Failed to execute job 67 for task get_variable_value
Traceback (most recent call last):
  File "/home/user/workspace/airflow/airflow_env/lib/python3.6/site-packages/airflow/task/task_runner/standard_task_runner.py", line 85, in _start_by_fork
    args.func(args, dag=self.dag)
  File "/home/user/workspace/airflow/airflow_env/lib/python3.6/site-packages/airflow/cli/cli_parser.py", line 48, in command
    return func(*args, **kwargs)
  File "/home/user/workspace/airflow/airflow_env/lib/python3.6/site-packages/airflow/utils/cli.py", line 92, in wrapper
    return f(*args, **kwargs)
  File "/home/user/workspace/airflow/airflow_env/lib/python3.6/site-packages/airflow/cli/commands/task_command.py", line 292, in task_run
    _run_task_by_selected_method(args, dag, ti)
  File "/home/user/workspace/airflow/airflow_env/lib/python3.6/site-packages/airflow/cli/commands/task_command.py", line 107, in _run_task_by_selected_method
    _run_raw_task(args, ti)
  File "/home/user/workspace/airflow/airflow_env/lib/python3.6/site-packages/airflow/cli/commands/task_command.py", line 184, in _run_raw_task
    error_file=args.error_file,
  File "/home/user/workspace/airflow/airflow_env/lib/python3.6/site-packages/airflow/utils/session.py", line 70, in wrapper
    return func(*args, session=session, **kwargs)
  File "/home/user/workspace/airflow/airflow_env/lib/python3.6/site-packages/airflow/models/taskinstance.py", line 1324, in _run_raw_task
    self._execute_task_with_callbacks(context)
  File "/home/user/workspace/airflow/airflow_env/lib/python3.6/site-packages/airflow/models/taskinstance.py", line 1406, in _execute_task_with_callbacks
    self.render_templates(context=context)
  File "/home/user/workspace/airflow/airflow_env/lib/python3.6/site-packages/airflow/models/taskinstance.py", line 2088, in render_templates
    self.task.render_template_fields(context)
  File "/home/user/workspace/airflow/airflow_env/lib/python3.6/site-packages/airflow/models/baseoperator.py", line 1057, in render_template_fields
    self._do_render_template_fields(self, self.template_fields, context, jinja_env, set())
  File "/home/user/workspace/airflow/airflow_env/lib/python3.6/site-packages/airflow/models/baseoperator.py", line 1070, in _do_render_template_fields
    rendered_content = self.render_template(content, context, jinja_env, seen_oids)
  File "/home/user/workspace/airflow/airflow_env/lib/python3.6/site-packages/airflow/models/baseoperator.py", line 1107, in render_template
    return jinja_env.from_string(content).render(**context)
  File "/home/user/workspace/airflow/airflow_env/lib/python3.6/site-packages/jinja2/environment.py", line 1090, in render
    self.environment.handle_exception()
  File "/home/user/workspace/airflow/airflow_env/lib/python3.6/site-packages/jinja2/environment.py", line 832, in handle_exception
    reraise(*rewrite_traceback_stack(source=source))
  File "/home/user/workspace/airflow/airflow_env/lib/python3.6/site-packages/jinja2/_compat.py", line 28, in reraise
    raise value.with_traceback(tb)
  File "<template>", line 1, in top-level template code
  File "/home/user/workspace/airflow/airflow_env/lib/python3.6/site-packages/jinja2/sandbox.py", line 407, in getattr
    value = getattr(obj, attribute)
  File "/home/user/workspace/airflow/airflow_env/lib/python3.6/site-packages/airflow/models/taskinstance.py", line 1841, in __getattr__
    self.var = Variable.get(item)
  File "/home/user/workspace/airflow/airflow_env/lib/python3.6/site-packages/airflow/models/variable.py", line 140, in get
    raise KeyError(f'Variable {key} does not exist')
KeyError: 'Variable val3 does not exist'
[2021-10-14 17:35:20,412] {local_task_job.py:154} INFO - Task exited with return code 1
[2021-10-14 17:35:20,434] {local_task_job.py:264} INFO - 0 downstream tasks scheduled from follow-on schedule check
